2021-04-19 18:20:29,288 ERROR: Exception on /user/da [GET] [in /home/axolotl/OOAD_py_blog/python-blog/venv/lib/python3.6/site-packages/flask/app.py:1892]
Traceback (most recent call last):
  File "/home/axolotl/OOAD_py_blog/python-blog/venv/lib/python3.6/site-packages/flask/app.py", line 2447, in wsgi_app
    response = self.full_dispatch_request()
  File "/home/axolotl/OOAD_py_blog/python-blog/venv/lib/python3.6/site-packages/flask/app.py", line 1952, in full_dispatch_request
    rv = self.handle_user_exception(e)
  File "/home/axolotl/OOAD_py_blog/python-blog/venv/lib/python3.6/site-packages/flask/app.py", line 1821, in handle_user_exception
    reraise(exc_type, exc_value, tb)
  File "/home/axolotl/OOAD_py_blog/python-blog/venv/lib/python3.6/site-packages/flask/_compat.py", line 39, in reraise
    raise value
  File "/home/axolotl/OOAD_py_blog/python-blog/venv/lib/python3.6/site-packages/flask/app.py", line 1950, in full_dispatch_request
    rv = self.dispatch_request()
  File "/home/axolotl/OOAD_py_blog/python-blog/venv/lib/python3.6/site-packages/flask/app.py", line 1936, in dispatch_request
    return self.view_functions[rule.endpoint](**req.view_args)
  File "/home/axolotl/OOAD_py_blog/python-blog/venv/lib/python3.6/site-packages/flask_login/utils.py", line 272, in decorated_view
    return func(*args, **kwargs)
  File "/home/axolotl/OOAD_py_blog/python-blog/app/routes.py", line 117, in user
    return render_template('user.html', user=user, posts=posts.items, next_url=next_url, prev_url=prev_url)
  File "/home/axolotl/OOAD_py_blog/python-blog/venv/lib/python3.6/site-packages/flask/templating.py", line 140, in render_template
    ctx.app,
  File "/home/axolotl/OOAD_py_blog/python-blog/venv/lib/python3.6/site-packages/flask/templating.py", line 120, in _render
    rv = template.render(context)
  File "/home/axolotl/OOAD_py_blog/python-blog/venv/lib/python3.6/site-packages/jinja2/environment.py", line 1090, in render
    self.environment.handle_exception()
  File "/home/axolotl/OOAD_py_blog/python-blog/venv/lib/python3.6/site-packages/jinja2/environment.py", line 832, in handle_exception
    reraise(*rewrite_traceback_stack(source=source))
  File "/home/axolotl/OOAD_py_blog/python-blog/venv/lib/python3.6/site-packages/jinja2/_compat.py", line 28, in reraise
    raise value.with_traceback(tb)
  File "/home/axolotl/OOAD_py_blog/python-blog/app/templates/user.html", line 1, in top-level template code
    {% extends "base.html" %}
  File "/home/axolotl/OOAD_py_blog/python-blog/app/templates/base.html", line 1, in top-level template code
    {% extends 'bootstrap/base.html' %}
  File "/home/axolotl/OOAD_py_blog/python-blog/venv/lib/python3.6/site-packages/flask_bootstrap/templates/bootstrap/base.html", line 1, in top-level template code
    {% block doc -%}
  File "/home/axolotl/OOAD_py_blog/python-blog/venv/lib/python3.6/site-packages/flask_bootstrap/templates/bootstrap/base.html", line 4, in block "doc"
    {%- block html %}
  File "/home/axolotl/OOAD_py_blog/python-blog/venv/lib/python3.6/site-packages/flask_bootstrap/templates/bootstrap/base.html", line 20, in block "html"
    {% block body -%}
  File "/home/axolotl/OOAD_py_blog/python-blog/venv/lib/python3.6/site-packages/flask_bootstrap/templates/bootstrap/base.html", line 23, in block "body"
    {% block content -%}
  File "/home/axolotl/OOAD_py_blog/python-blog/app/templates/base.html", line 49, in block "content"
    {% block app_content %}{% endblock %}
  File "/home/axolotl/OOAD_py_blog/python-blog/app/templates/user.html", line 23, in block "app_content"
    {% include '_post.html' %}
  File "/home/axolotl/OOAD_py_blog/python-blog/app/templates/_post.html", line 17, in top-level template code
    <p><a href="{{ url_for('edit_post') }}">Edit your post</a></p>
  File "/home/axolotl/OOAD_py_blog/python-blog/venv/lib/python3.6/site-packages/flask/helpers.py", line 370, in url_for
    return appctx.app.handle_url_build_error(error, endpoint, values)
  File "/home/axolotl/OOAD_py_blog/python-blog/venv/lib/python3.6/site-packages/flask/app.py", line 2216, in handle_url_build_error
    reraise(exc_type, exc_value, tb)
  File "/home/axolotl/OOAD_py_blog/python-blog/venv/lib/python3.6/site-packages/flask/_compat.py", line 39, in reraise
    raise value
  File "/home/axolotl/OOAD_py_blog/python-blog/venv/lib/python3.6/site-packages/flask/helpers.py", line 358, in url_for
    endpoint, values, method=method, force_external=external
  File "/home/axolotl/OOAD_py_blog/python-blog/venv/lib/python3.6/site-packages/werkzeug/routing.py", line 2179, in build
    raise BuildError(endpoint, values, method, self)
werkzeug.routing.BuildError: Could not build url for endpoint 'edit_post'. Did you mean 'edit_profile' instead?
2021-04-19 18:26:12,620 INFO: python-blog startup [in /home/axolotl/OOAD_py_blog/python-blog/app/__init__.py:36]
2021-04-19 18:27:26,333 INFO: python-blog startup [in /home/axolotl/OOAD_py_blog/python-blog/app/__init__.py:36]
2021-04-19 18:27:30,991 ERROR: Exception on /edit_post [GET] [in /home/axolotl/OOAD_py_blog/python-blog/venv/lib/python3.6/site-packages/flask/app.py:1892]
Traceback (most recent call last):
  File "/home/axolotl/OOAD_py_blog/python-blog/venv/lib/python3.6/site-packages/flask/app.py", line 2447, in wsgi_app
    response = self.full_dispatch_request()
  File "/home/axolotl/OOAD_py_blog/python-blog/venv/lib/python3.6/site-packages/flask/app.py", line 1952, in full_dispatch_request
    rv = self.handle_user_exception(e)
  File "/home/axolotl/OOAD_py_blog/python-blog/venv/lib/python3.6/site-packages/flask/app.py", line 1821, in handle_user_exception
    reraise(exc_type, exc_value, tb)
  File "/home/axolotl/OOAD_py_blog/python-blog/venv/lib/python3.6/site-packages/flask/_compat.py", line 39, in reraise
    raise value
  File "/home/axolotl/OOAD_py_blog/python-blog/venv/lib/python3.6/site-packages/flask/app.py", line 1950, in full_dispatch_request
    rv = self.dispatch_request()
  File "/home/axolotl/OOAD_py_blog/python-blog/venv/lib/python3.6/site-packages/flask/app.py", line 1936, in dispatch_request
    return self.view_functions[rule.endpoint](**req.view_args)
  File "/home/axolotl/OOAD_py_blog/python-blog/venv/lib/python3.6/site-packages/flask_login/utils.py", line 272, in decorated_view
    return func(*args, **kwargs)
TypeError: edit_post() missing 1 required positional argument: 'post'
2021-04-19 18:29:40,335 ERROR: Exception on /edit_post [GET] [in /home/axolotl/OOAD_py_blog/python-blog/venv/lib/python3.6/site-packages/flask/app.py:1892]
Traceback (most recent call last):
  File "/home/axolotl/OOAD_py_blog/python-blog/venv/lib/python3.6/site-packages/flask/app.py", line 2447, in wsgi_app
    response = self.full_dispatch_request()
  File "/home/axolotl/OOAD_py_blog/python-blog/venv/lib/python3.6/site-packages/flask/app.py", line 1952, in full_dispatch_request
    rv = self.handle_user_exception(e)
  File "/home/axolotl/OOAD_py_blog/python-blog/venv/lib/python3.6/site-packages/flask/app.py", line 1821, in handle_user_exception
    reraise(exc_type, exc_value, tb)
  File "/home/axolotl/OOAD_py_blog/python-blog/venv/lib/python3.6/site-packages/flask/_compat.py", line 39, in reraise
    raise value
  File "/home/axolotl/OOAD_py_blog/python-blog/venv/lib/python3.6/site-packages/flask/app.py", line 1950, in full_dispatch_request
    rv = self.dispatch_request()
  File "/home/axolotl/OOAD_py_blog/python-blog/venv/lib/python3.6/site-packages/flask/app.py", line 1936, in dispatch_request
    return self.view_functions[rule.endpoint](**req.view_args)
  File "/home/axolotl/OOAD_py_blog/python-blog/venv/lib/python3.6/site-packages/flask_login/utils.py", line 272, in decorated_view
    return func(*args, **kwargs)
TypeError: edit_post() missing 1 required positional argument: 'post'
2021-04-19 18:32:57,772 INFO: python-blog startup [in /home/axolotl/OOAD_py_blog/python-blog/app/__init__.py:36]
2021-04-19 18:33:00,945 ERROR: Exception on /edit_post/<Post dasdad> [GET] [in /home/axolotl/OOAD_py_blog/python-blog/venv/lib/python3.6/site-packages/flask/app.py:1892]
Traceback (most recent call last):
  File "/home/axolotl/OOAD_py_blog/python-blog/venv/lib/python3.6/site-packages/flask/app.py", line 2447, in wsgi_app
    response = self.full_dispatch_request()
  File "/home/axolotl/OOAD_py_blog/python-blog/venv/lib/python3.6/site-packages/flask/app.py", line 1952, in full_dispatch_request
    rv = self.handle_user_exception(e)
  File "/home/axolotl/OOAD_py_blog/python-blog/venv/lib/python3.6/site-packages/flask/app.py", line 1821, in handle_user_exception
    reraise(exc_type, exc_value, tb)
  File "/home/axolotl/OOAD_py_blog/python-blog/venv/lib/python3.6/site-packages/flask/_compat.py", line 39, in reraise
    raise value
  File "/home/axolotl/OOAD_py_blog/python-blog/venv/lib/python3.6/site-packages/flask/app.py", line 1950, in full_dispatch_request
    rv = self.dispatch_request()
  File "/home/axolotl/OOAD_py_blog/python-blog/venv/lib/python3.6/site-packages/flask/app.py", line 1936, in dispatch_request
    return self.view_functions[rule.endpoint](**req.view_args)
  File "/home/axolotl/OOAD_py_blog/python-blog/venv/lib/python3.6/site-packages/flask_login/utils.py", line 272, in decorated_view
    return func(*args, **kwargs)
  File "/home/axolotl/OOAD_py_blog/python-blog/app/routes.py", line 146, in edit_post
    form.post.data = post.data
AttributeError: 'str' object has no attribute 'data'
2021-04-19 18:33:40,085 INFO: python-blog startup [in /home/axolotl/OOAD_py_blog/python-blog/app/__init__.py:36]
